<?xml version='1.0'?>
<sdf version='1.4'>
  <model name='scipio_simulation'>
    <link name='base_link'>
      <pose>0 0 0 0 -0 0</pose>
      <inertial>
        <pose>0.00808696 0.174209 -5.1079e-07 0 -0 0</pose>
        <mass>30.6648</mass>
        <inertia>
          <ixx>2.53655</ixx>
          <ixy>-0.0102253</ixy>
          <ixz>1.17409e-05</ixz>
          <iyy>4.29926</iyy>
          <iyz>1.93444e-07</iyz>
          <izz>2.13276</izz>
        </inertia>
      </inertial>
      <collision name='base_link_collision'>
        <pose>0 0 0 0 -0 0</pose>
        <geometry>
          <mesh>
            <scale>1 1 1</scale>
            <uri>model://scipio_simulation/meshes/base_link.STL</uri>
          </mesh>
        </geometry>
      </collision>
      <visual name='base_link_visual'>
        <pose>0.053 0 0 0 -0 0</pose>
        <geometry>
          <mesh>
            <scale>1 1 1</scale>
            <uri>model://scipio_simulation/meshes/base_link.DAE</uri>
          </mesh>
        </geometry>
      </visual>
      <velocity_decay>
        <linear>0</linear>
        <angular>0</angular>
      </velocity_decay>
    </link>

    <link name='back_left_wheel_link'>
      <pose>0.26746 -0.17757 0.18923 3.0728 -6.245e-17 -1.5708</pose>
      <inertial>
        <pose>0.24702 -3.7896e-07 7.5693e-06 0 -0 0</pose>
        <mass>11.018</mass>
        <inertia>
          <ixx>0.20289</ixx>
          <ixy>2.1691e-07</ixy>
          <ixz>-4.2814e-06</ixz>
          <iyy>0.1147</iyy>
          <iyz>3.8435e-08</iyz>
          <izz>0.1147</izz>
        </inertia>
      </inertial>
      <collision name='back_left_wheel_link_collision'>
        <pose>0 0 0 0 -0 0</pose>
        <geometry>
          <mesh>
            <scale>1 1 1</scale>
            <uri>model://scipio_simulation/meshes/back_left_wheel_link.STL</uri>
          </mesh>
        </geometry>
      </collision>
      <visual name='back_left_wheel_link_visual'>
        <pose>0 0 0 0 -0 0</pose>
        <geometry>
          <mesh>
            <scale>1 1 1</scale>
            <uri>model://scipio_simulation/meshes/back_left_wheel_link.STL</uri>
          </mesh>
        </geometry>
        <material>
          <script>
            <uri>file://media/materials/scripts/gazebo.material</uri>
            <name>Gazebo/Grey</name>
          </script>
        </material>
      </visual>
      <velocity_decay>
        <linear>0</linear>
        <angular>0</angular>
      </velocity_decay>
    </link>
    <joint name='back_left_wheel_joint' type='revolute'>
      <child>back_left_wheel_link</child>
      <parent>base_link</parent>
      <axis>
        <xyz>3.67321e-06 1 -5.89806e-17</xyz>
        <limit>
          <lower>-1e+16</lower>
          <upper>1e+16</upper>
        </limit>
      </axis>
    </joint>

    <link name='back_right_wheel_link'>
      <pose>0.26746 0.17757 0.18923 -3.0192 5.55112e-17 1.5708</pose>
      <inertial>
        <pose>0.24702 -2.4732e-06 -7.1639e-06 0 -0 0</pose>
        <mass>11.018</mass>
        <inertia>
          <ixx>0.20289</ixx>
          <ixy>1.3965e-06</ixy>
          <ixz>4.0531e-06</ixz>
          <iyy>0.1147</iyy>
          <iyz>-2.2566e-07</iyz>
          <izz>0.1147</izz>
        </inertia>
      </inertial>
      <collision name='back_right_wheel_link_collision'>
        <pose>0 0 0 0 -0 0</pose>
        <geometry>
          <mesh>
            <scale>1 1 1</scale>
            <uri>model://scipio_simulation/meshes/back_right_wheel_link.STL</uri>
          </mesh>
        </geometry>
      </collision>
      <visual name='back_right_wheel_link_visual'>
        <pose>0 0 0 0 -0 0</pose>
        <geometry>
          <mesh>
            <scale>1 1 1</scale>
            <uri>model://scipio_simulation/meshes/back_right_wheel_link.STL</uri>
          </mesh>
        </geometry>
        <material>
          <script>
            <uri>file://media/materials/scripts/gazebo.material</uri>
            <name>Gazebo/Grey</name>
          </script>
        </material>
      </visual>
      <velocity_decay>
        <linear>0</linear>
        <angular>0</angular>
      </velocity_decay>
    </link>
    <joint name='back_right_wheel_joint' type='revolute'>
      <child>back_right_wheel_link</child>
      <parent>base_link</parent>
      <axis>
        <xyz>-3.67321e-06 1 -5.55112e-17</xyz>
        <limit>
          <lower>-1e+16</lower>
          <upper>1e+16</upper>
        </limit>
      </axis>
    </joint>

    <link name='front_left_wheel_link'>
      <pose>-0.26746 -0.17757 0.18923 3.0516 -5.55112e-17 -1.5708</pose>
      <inertial>
        <pose>0.24702 -6.9913e-07 7.5465e-06 0 -0 0</pose>
        <mass>11.018</mass>
        <inertia>
          <ixx>0.20289</ixx>
          <ixy>3.9801e-07</ixy>
          <ixz>-4.2684e-06</ixz>
          <iyy>0.1147</iyy>
          <iyz>6.9259e-08</iyz>
          <izz>0.1147</izz>
        </inertia>
      </inertial>
      <collision name='front_left_wheel_link_collision'>
        <pose>0 0 0 0 -0 0</pose>
        <geometry>
          <mesh>
            <scale>1 1 1</scale>
            <uri>model://scipio_simulation/meshes/front_left_wheel_link.STL</uri>
          </mesh>
        </geometry>
      </collision>
      <visual name='front_left_wheel_link_visual'>
        <pose>0 0 0 0 -0 0</pose>
        <geometry>
          <mesh>
            <scale>1 1 1</scale>
            <uri>model://scipio_simulation/meshes/front_left_wheel_link.STL</uri>
          </mesh>
        </geometry>
        <material>
          <script>
            <uri>file://media/materials/scripts/gazebo.material</uri>
            <name>Gazebo/Grey</name>
          </script>
        </material>
      </visual>
      <velocity_decay>
        <linear>0</linear>
        <angular>0</angular>
      </velocity_decay>
    </link>
    <joint name='front_left_wheel_joint' type='revolute'>
      <child>front_left_wheel_link</child>
      <parent>base_link</parent>
      <axis>
        <xyz>3.67321e-06 1 -5.55112e-17</xyz>
        <limit>
          <lower>-1e+16</lower>
          <upper>1e+16</upper>
        </limit>
      </axis>
    </joint>

    <link name='front_right_wheel_link'>
      <pose>-0.26746 0.17757 0.18923 -3.1282 5.81132e-17 1.5708</pose>
      <inertial>
        <pose>0.24702 -8.6541e-07 -7.5292e-06 0 -0 0</pose>
        <mass>11.018</mass>
        <inertia>
          <ixx>0.20289</ixx>
          <ixy>4.8698e-07</ixy>
          <ixz>4.2592e-06</ixz>
          <iyy>0.1147</iyy>
          <iyz>-8.183e-08</iyz>
          <izz>0.1147</izz>
        </inertia>
      </inertial>
      <collision name='front_right_wheel_link_collision'>
        <pose>0 0 0 0 -0 0</pose>
        <geometry>
          <mesh>
            <scale>1 1 1</scale>
            <uri>model://scipio_simulation/meshes/front_right_wheel_link.STL</uri>
          </mesh>
        </geometry>
      </collision>
      <visual name='front_right_wheel_link_visual'>
        <pose>0 0 0 0 -0 0</pose>
        <geometry>
          <mesh>
            <scale>1 1 1</scale>
            <uri>model://scipio_simulation/meshes/front_right_wheel_link.STL</uri>
          </mesh>
        </geometry>
        <material>
          <script>
            <uri>file://media/materials/scripts/gazebo.material</uri>
            <name>Gazebo/Grey</name>
          </script>
        </material>
      </visual>
      <velocity_decay>
        <linear>0</linear>
        <angular>0</angular>
      </velocity_decay>
    </link>
    <joint name='front_right_wheel_joint' type='revolute'>
      <child>front_right_wheel_link</child>
      <parent>base_link</parent>
      <axis>
        <xyz>-3.67321e-06 1 -5.9848e-17</xyz>
        <limit>
          <lower>-1e+16</lower>
          <upper>1e+16</upper>
        </limit>
      </axis>
    </joint>

      <link name='imu_link'>
         <inertial>
            <pose>0 0 0 0 0 0</pose>
            <mass>0.001</mass>
            <inertia>
                <ixx>1e-09</ixx>
                <ixy>0</ixy>
                <ixz>0</ixz>
                <iyy>1e-09</iyy>
                <iyz>0</iyz>
                <izz>1e-09</izz>
            </inertia>
          </inertial>
      </link>
      <joint name='imu_joint' type='revolute'>
          <child>imu_link</child>
          <parent>base_link</parent>
          <axis>
              <xyz>0 0 1</xyz>
       	      <limit>
                 <lower>0</lower>
                 <upper>0</upper>
              </limit>
          </axis>
      </joint>

      <link name='gps_link'>
         <inertial>
            <pose>0 0 0 0 0 0</pose>
            <mass>0.001</mass>
            <inertia>
                <ixx>1e-09</ixx>
                <ixy>0</ixy>
                <ixz>0</ixz>
                <iyy>1e-09</iyy>
                <iyz>0</iyz>
                <izz>1e-09</izz>
            </inertia>
          </inertial>
      </link>
      <joint name='gps_joint' type='revolute'>
	  <pose>0 0 0 0 0 0</pose>
          <child>gps_link</child>
          <parent>base_link</parent>
          <axis>
              <xyz>0 0 1</xyz>
              <limit>
                 <lower>0</lower>
                 <upper>0</upper>
              </limit>
          </axis>
      </joint>


     <plugin name="skid_steer_drive_controller" filename="libgazebo_ros_skid_steer_drive.so">
   	<updateRate>35.0</updateRate>
   	<robotNamespace>/</robotNamespace>
   	<leftFrontJoint>back_right_wheel_joint</leftFrontJoint>
   	<rightFrontJoint>back_left_wheel_joint</rightFrontJoint>
   	<leftRearJoint>front_right_wheel_joint</leftRearJoint>
   	<rightRearJoint>front_left_wheel_joint</rightRearJoint>
   	<wheelSeparation>0.854431</wheelSeparation>
   	<wheelDiameter>0.379476</wheelDiameter>
   	<robotBaseFrame>base_footprint</robotBaseFrame>
   	<torque>40</torque>
   	<commandTopic>cmd_vel</commandTopic>
	<odometryTopic>raw_odom</odometryTopic>
	<odometryFrame>odom</odometryFrame>
     </plugin> 

	<plugin name="gps_controller" filename="libhector_gazebo_ros_gps.so">
		<updateRate>40</updateRate>
		<robotNamespace>/</robotNamespace>
		<bodyName>gps_link</bodyName>
		<frameId>base_footprint</frameId>
		<topicName>fix</topicName>
		<velocityTopicName>/navsat/vel</velocityTopicName>
		<referenceLatitude>49.9</referenceLatitude>
		<referenceLongitude>8.9</referenceLongitude>
		<referenceHeading>0</referenceHeading>
		<referenceAltitude>0</referenceAltitude>
		<drift>0.0000 0.0000 0.0000</drift>
	</plugin>
<!--
    <plugin name="novatel_gps_sim" filename="libhector_gazebo_ros_gps.so">
            <alwaysOn>1</alwaysOn>
            <frameId>gps</frameId>
            <updateRate>20</updateRate>
            <bodyName>base_footprint</bodyName>
            <topicName>fix</topicName>
            <velocityTopicName>fix_velocity</velocityTopicName>
            <drift>0 0 0</drift>
            <gaussianNoise>0 0 0</gaussianNoise>
            <velocityDrift>0 0 0</velocityDrift>
            <velocityGaussianNoise>0 0 0</velocityGaussianNoise>
        </plugin>
-->
	<plugin name="imu_controller" filename="libhector_gazebo_ros_imu.so">
		<robotNamespace>/</robotNamespace>
		<updateRate>50.0</updateRate>
		<bodyName>base_footprint</bodyName>
		<topicName>imu/data</topicName>
		<accelDrift>0.00 0.00 0.00</accelDrift>
		<accelGaussianNoise>0.00 0.00 0.00</accelGaussianNoise>
		<rateDrift>0.00 0.00 0.00</rateDrift>
		<rateGaussianNoise>0.00 0.00 0.00 </rateGaussianNoise>
		<headingDrift>0.00</headingDrift>
		<headingGaussianNoise>0.00</headingGaussianNoise>
	</plugin>

  </model>
</sdf>
