<?xml version='1.0'?>
<sdf version='1.4'>
  <model name='scipio_simulation'>
    <static>false</static>
    <pose>0 0 0.1 0 0 1.57</pose>
    <link name='base_link'>
      <pose>0 0 0 0 -0 0</pose>
      <inertial>
        <pose>0.00808696 0.174209 -5.1079e-07 0 -0 0</pose>
        <mass>30.6648</mass>
        <inertia>
          <ixx>2.53655</ixx>
          <ixy>-0.0102253</ixy>
          <ixz>1.17409e-05</ixz>
          <iyy>4.29926</iyy>
          <iyz>1.93444e-07</iyz>
          <izz>2.13276</izz>
        </inertia>
      </inertial>
      <collision name='base_link_collision'>
        <pose>0 0 0.5 0 -0 0</pose>
        <geometry>
           <box>
             <size>0.7 0.7 0.7</size>
           </box>
        </geometry>
      </collision>
      <visual name='base_link_visual'>
        <pose>0.049 0.009 0 0 -0 0</pose>
        <geometry>
          <mesh>
            <scale>1 1 1</scale>
            <uri>model://scipio_simulation/meshes/base_link.DAE</uri>
          </mesh>
        </geometry>
      </visual>
      <velocity_decay>
        <linear>0</linear>
        <angular>0</angular>
      </velocity_decay>
    </link>

    <link name='back_left_wheel_link'>
      <pose>0.26746 -0.17757 0.18923 3.0728 -6.245e-17 -1.5708</pose>
      <inertial>
        <pose>0.24702 -3.7896e-07 7.5693e-06 0 -0 0</pose>
        <mass>11.018</mass>
        <inertia>
          <ixx>0.20289</ixx>
          <ixy>2.1691e-07</ixy>
          <ixz>-4.2814e-06</ixz>
          <iyy>0.1147</iyy>
          <iyz>3.8435e-08</iyz>
          <izz>0.1147</izz>
        </inertia>
      </inertial>
      <collision name='back_left_wheel_link_collision'>
        <pose>0 0 0 0 -0 0</pose>
        <geometry>
          <mesh>
            <scale>1 1 1</scale>
            <uri>model://scipio_simulation/meshes/back_left_wheel_link.STL</uri>
          </mesh>
<!--
          <cylinder>
             <radius>0.0165</radius>
             <length>0.08</radius>
          </cylinder>
This wont work yet because we also need a cylinder for the axel -->
        </geometry>
      </collision>
      <visual name='back_left_wheel_link_visual'>
        <pose>0 0 0 0 -0 0</pose>
        <geometry>
          <mesh>
            <scale>1 1 1</scale>
            <uri>model://scipio_simulation/meshes/back_left_wheel_link.STL</uri>
          </mesh>
        </geometry>
        <material>
          <script>
            <uri>file://media/materials/scripts/gazebo.material</uri>
            <name>Gazebo/Grey</name>
          </script>
        </material>
      </visual>
      <velocity_decay>
        <linear>0</linear>
        <angular>0</angular>
      </velocity_decay>
    </link>
    <joint name='back_left_wheel_joint' type='revolute'>
      <child>back_left_wheel_link</child>
      <parent>base_link</parent>
      <axis>
        <xyz>3.67321e-06 1 -5.89806e-17</xyz>
        <limit>
          <lower>-1e+16</lower>
          <upper>1e+16</upper>
        </limit>
      </axis>
    </joint>

    <link name='back_right_wheel_link'>
      <pose>0.26746 0.17757 0.18923 -3.0192 5.55112e-17 1.5708</pose>
      <inertial>
        <pose>0.24702 -2.4732e-06 -7.1639e-06 0 -0 0</pose>
        <mass>11.018</mass>
        <inertia>
          <ixx>0.20289</ixx>
          <ixy>1.3965e-06</ixy>
          <ixz>4.0531e-06</ixz>
          <iyy>0.1147</iyy>
          <iyz>-2.2566e-07</iyz>
          <izz>0.1147</izz>
        </inertia>
      </inertial>
      <collision name='back_right_wheel_link_collision'>
        <pose>0 0 0 0 -0 0</pose>
        <geometry>
          <mesh>
            <scale>1 1 1</scale>
            <uri>model://scipio_simulation/meshes/back_right_wheel_link.STL</uri>
          </mesh>
        </geometry>
      </collision>
      <visual name='back_right_wheel_link_visual'>
        <pose>0 0 0 0 -0 0</pose>
        <geometry>
          <mesh>
            <scale>1 1 1</scale>
            <uri>model://scipio_simulation/meshes/back_right_wheel_link.STL</uri>
          </mesh>
        </geometry>
        <material>
          <script>
            <uri>file://media/materials/scripts/gazebo.material</uri>
            <name>Gazebo/Grey</name>
          </script>
        </material>
      </visual>
      <velocity_decay>
        <linear>0</linear>
        <angular>0</angular>
      </velocity_decay>
    </link>
    <joint name='back_right_wheel_joint' type='revolute'>
      <child>back_right_wheel_link</child>
      <parent>base_link</parent>
      <axis>
        <xyz>-3.67321e-06 1 -5.55112e-17</xyz>
        <limit>
          <lower>-1e+16</lower>
          <upper>1e+16</upper>
        </limit>
      </axis>
    </joint>

    <link name='front_left_wheel_link'>
      <pose>-0.26746 -0.17757 0.18923 3.0516 -5.55112e-17 -1.5708</pose>
      <inertial>
        <pose>0.24702 -6.9913e-07 7.5465e-06 0 -0 0</pose>
        <mass>11.018</mass>
        <inertia>
          <ixx>0.20289</ixx>
          <ixy>3.9801e-07</ixy>
          <ixz>-4.2684e-06</ixz>
          <iyy>0.1147</iyy>
          <iyz>6.9259e-08</iyz>
          <izz>0.1147</izz>
        </inertia>
      </inertial>
      <collision name='front_left_wheel_link_collision'>
        <pose>0 0 0 0 -0 0</pose>
        <geometry>
          <mesh>
            <scale>1 1 1</scale>
            <uri>model://scipio_simulation/meshes/front_left_wheel_link.STL</uri>
          </mesh>
        </geometry>
      </collision>
      <visual name='front_left_wheel_link_visual'>
        <pose>0 0 0 0 -0 0</pose>
        <geometry>
          <mesh>
            <scale>1 1 1</scale>
            <uri>model://scipio_simulation/meshes/front_left_wheel_link.STL</uri>
          </mesh>
        </geometry>
        <material>
          <script>
            <uri>file://media/materials/scripts/gazebo.material</uri>
            <name>Gazebo/Grey</name>
          </script>
        </material>
      </visual>
      <velocity_decay>
        <linear>0</linear>
        <angular>0</angular>
      </velocity_decay>
    </link>
    <joint name='front_left_wheel_joint' type='revolute'>
      <child>front_left_wheel_link</child>
      <parent>base_link</parent>
      <axis>
        <xyz>3.67321e-06 1 -5.55112e-17</xyz>
        <limit>
          <lower>-1e+16</lower>
          <upper>1e+16</upper>
        </limit>
      </axis>
    </joint>

    <link name='front_right_wheel_link'>
      <pose>-0.26746 0.17757 0.18923 -3.1282 5.81132e-17 1.5708</pose>
      <inertial>
        <pose>0.24702 -8.6541e-07 -7.5292e-06 0 -0 0</pose>
        <mass>11.018</mass>
        <inertia>
          <ixx>0.20289</ixx>
          <ixy>4.8698e-07</ixy>
          <ixz>4.2592e-06</ixz>
          <iyy>0.1147</iyy>
          <iyz>-8.183e-08</iyz>
          <izz>0.1147</izz>
        </inertia>
      </inertial>
      <collision name='front_right_wheel_link_collision'>
        <pose>0 0 0 0 -0 0</pose>
        <geometry>
          <mesh>
            <scale>1 1 1</scale>
            <uri>model://scipio_simulation/meshes/front_right_wheel_link.STL</uri>
          </mesh>
        </geometry>
      </collision>
      <visual name='front_right_wheel_link_visual'>
        <pose>0 0 0 0 -0 0</pose>
        <geometry>
          <mesh>
            <scale>1 1 1</scale>
            <uri>model://scipio_simulation/meshes/front_right_wheel_link.STL</uri>
          </mesh>
        </geometry>
        <material>
          <script>
            <uri>file://media/materials/scripts/gazebo.material</uri>
            <name>Gazebo/Grey</name>
          </script>
        </material>
      </visual>
      <velocity_decay>
        <linear>0</linear>
        <angular>0</angular>
      </velocity_decay>
    </link>
    <joint name='front_right_wheel_joint' type='revolute'>
      <child>front_right_wheel_link</child>
      <parent>base_link</parent>
      <axis>
        <xyz>-3.67321e-06 1 -5.9848e-17</xyz>
        <limit>
          <lower>-1e+16</lower>
          <upper>1e+16</upper>
        </limit>
      </axis>
    </joint>

    <joint name="bumblebee_mount_joint" type="revolute">
      <parent>base_link</parent>
      <child>bumblebee_mount_link</child>
      <pose>0 0 0 0 0 0</pose>
      <axis>
        <xyz>-1 0 0</xyz>
        <limit>
          <lower>0</lower>
          <upper>0</upper>
        </limit>
      </axis>
    </joint>

    <link name='bumblebee_mount_link'>
      <pose>0.2 0 0.85 2.04 0 1.57</pose>
      <inertial>
        <mass>0.687646</mass>
        <inertia>
          <ixx>0.000101</ixx>
          <ixy>0.0</ixy>
          <ixz>0.0</ixz>
          <iyy>0.000767</iyy>
          <iyz>0.0</iyz>
          <izz>0.000739</izz>
        </inertia>
      </inertial>
      <collision name='bumblebee_mount_link_collision'>
        <pose>0 0 0 0 0 0</pose>
        <geometry>
          <mesh>
            <scale>1 1 1</scale>
            <uri>model://lcsr_camera_models/cameras/bumblebee/bumblebee2.dae</uri>
          </mesh>
        </geometry>
      </collision>
      <visual name='bumblebee_mount_link_visual'>
        <pose>0 0 0 0 0 0</pose>
        <geometry>
          <mesh>
            <scale>1 1 1</scale>
            <uri>model://lcsr_camera_models/cameras/bumblebee/bumblebee2.dae</uri>
          </mesh>
        </geometry>
      </visual>
      <gravity>1</gravity>
      <velocity_decay>
         <linear>0</linear>
         <angular>0</angular>
      </velocity_decay>
      <self_collide>0</self_collide>

    <sensor name='stereo_camera' type='multicamera'>
       <update_rate>48</update_rate>
       <camera name='left'>
          <pose>0.06 0 0 -5.76279e-13 -1.5707 -1.5707</pose>
          <horizontal_fov>1.15192</horizontal_fov>
            <image>
              <width>640</width>
              <height>480</height>
              <format>R8G8B8</format>
            </image>
            <clip>
              <near>0.05</near>
              <far>300</far>
            </clip>
            <noise>
              <type>gaussian</type>
              <mean>0</mean>
              <stddev>0.007</stddev>
            </noise>
        </camera>
        <camera name='right'>
          <pose>-0.06 0 0 -5.76279e-13 -1.5707 -1.5707</pose>
            <horizontal_fov>1.15192</horizontal_fov>
            <image>
              <width>640</width>
              <height>480</height>
              <format>R8G8B8</format>
            </image>
            <clip>
              <near>0.05</near>
              <far>300</far>
            </clip>
            <noise>
              <type>gaussian</type>
              <mean>0</mean>
              <stddev>0.007</stddev>
            </noise>
         </camera>

       <plugin name='stereo_camera_controller' filename='libgazebo_ros_multicamera.so'>
          <alwaysOn>true</alwaysOn>
          <cameraName>stereo_camera</cameraName>
          <imageTopicName>image_raw</imageTopicName>
          <cameraInfoTopicName>camera_info</cameraInfoTopicName>
          <frameName>bumblebee_mount_link</frameName>
          <hackBaseline>0.12</hackBaseline>
          <distortionK1>0.0</distortionK1>
          <distortionK2>0.0</distortionK2>
          <distortionK3>0.0</distortionK3>
          <distortionT1>0.0</distortionT1>
          <distortionT2>0.0</distortionT2>
        </plugin>
       <pose>0 0 0 0 0 0</pose>
      </sensor>
     </link>

      <link name='imu_link'>
         <inertial>
            <pose>0 0 0 0 0 0</pose>
            <mass>0.001</mass>
            <inertia>
                <ixx>1e-09</ixx>
                <ixy>0</ixy>
                <ixz>0</ixz>
                <iyy>1e-09</iyy>
                <iyz>0</iyz>
                <izz>1e-09</izz>
            </inertia>
          </inertial>
      </link>
      <joint name='imu_joint' type='revolute'>
          <child>imu_link</child>
          <parent>base_link</parent>
          <axis>
              <xyz>0 0 1</xyz>
       	      <limit>
                 <lower>0</lower>
                 <upper>0</upper>
              </limit>
          </axis>
      </joint>

      <link name='gps_link'>
         <inertial>
            <pose>0 0 0 0 0 0</pose>
            <mass>0.001</mass>
            <inertia>
                <ixx>1e-09</ixx>
                <ixy>0</ixy>
                <ixz>0</ixz>
                <iyy>1e-09</iyy>
                <iyz>0</iyz>
                <izz>1e-09</izz>
            </inertia>
          </inertial>
      </link>
      <joint name='gps_joint' type='revolute'>
	  <pose>0 0 0 0 0 0</pose>
          <child>gps_link</child>
          <parent>base_link</parent>
          <axis>
              <xyz>0 0 1</xyz>
              <limit>
                 <lower>0</lower>
                 <upper>0</upper>
              </limit>
          </axis>
      </joint>


     <plugin name="skid_steer_drive_controller" filename="libgazebo_ros_skid_steer_drive.so">
   	<updateRate>35.0</updateRate>
   	<robotNamespace>/</robotNamespace>
   	<leftFrontJoint>back_right_wheel_joint</leftFrontJoint>
   	<rightFrontJoint>back_left_wheel_joint</rightFrontJoint>
   	<leftRearJoint>front_right_wheel_joint</leftRearJoint>
   	<rightRearJoint>front_left_wheel_joint</rightRearJoint>
   	<wheelSeparation>0.854431</wheelSeparation>
   	<wheelDiameter>0.379476</wheelDiameter>
   	<robotBaseFrame>base_footprint</robotBaseFrame>
   	<torque>40</torque>
   	<commandTopic>cmd_vel</commandTopic>
	<odometryTopic>raw_odom</odometryTopic>
	<odometryFrame>odom</odometryFrame>
     </plugin> 

	<plugin name="gps_controller" filename="libhector_gazebo_ros_gps.so">
		<updateRate>40</updateRate>
		<robotNamespace>/</robotNamespace>
		<bodyName>gps_link</bodyName>
		<frameId>base_footprint</frameId>
		<topicName>fix</topicName>
		<velocityTopicName>/navsat/vel</velocityTopicName>
		<referenceLatitude>49.9</referenceLatitude>
		<referenceLongitude>8.9</referenceLongitude>
		<referenceHeading>0</referenceHeading>
		<referenceAltitude>0</referenceAltitude>
		<drift>0.0000 0.0000 0.0000</drift>
	</plugin>
<!--
    <plugin name="novatel_gps_sim" filename="libhector_gazebo_ros_gps.so">
            <alwaysOn>1</alwaysOn>
            <frameId>gps</frameId>
            <updateRate>20</updateRate>
            <bodyName>base_footprint</bodyName>
            <topicName>fix</topicName>
            <velocityTopicName>fix_velocity</velocityTopicName>
            <drift>0 0 0</drift>
            <gaussianNoise>0 0 0</gaussianNoise>
            <velocityDrift>0 0 0</velocityDrift>
            <velocityGaussianNoise>0 0 0</velocityGaussianNoise>
        </plugin>
-->
	<plugin name="imu_controller" filename="libhector_gazebo_ros_imu.so">
		<robotNamespace>/</robotNamespace>
		<updateRate>50.0</updateRate>
		<bodyName>base_link</bodyName>
		<topicName>imu/data</topicName>
		<accelDrift>0.00 0.00 0.00</accelDrift>
		<accelGaussianNoise>0.00 0.00 0.00</accelGaussianNoise>
		<rateDrift>0.00 0.00 0.00</rateDrift>
		<rateGaussianNoise>0.00 0.00 0.00 </rateGaussianNoise>
		<headingDrift>0.00</headingDrift>
		<headingGaussianNoise>0.00</headingGaussianNoise>
	</plugin>


      <link name='laser'>
         <pose>0.428 0 0.485 0 0 0</pose>
         <inertial>
            <pose>0 0 0 0 0 0</pose>
            <mass>0.001</mass>
            <inertia>
                <ixx>1e-09</ixx>
                <ixy>0</ixy>
                <ixz>0</ixz>
                <iyy>1e-09</iyy>
                <iyz>0</iyz>
                <izz>1e-09</izz>
            </inertia>
          </inertial>

<sensor type="ray" name="laser">
<pose>0 0 0 0 0 0</pose>
<visualize>true</visualize>
<update_rate>15</update_rate>
<ray>
<scan>
<horizontal>
<samples>720</samples>
<resolution>1</resolution>
<min_angle>-1.570796</min_angle>
<max_angle>1.570796</max_angle>
</horizontal>
</scan>
<range>
<min>0.08</min>
<max>10.0</max>
<resolution>0.05</resolution>
</range>
<noise>
<type>gaussian</type>
<mean>0.0</mean>
<stddev>0.000</stddev>
</noise>
</ray>
<plugin name="gazebo_ros_laser" filename="libgazebo_ros_laser.so">
<topicName>scan</topicName>
<frameName>laser</frameName>
</plugin>
</sensor>

      </link>

      <joint name='laser_joint' type='revolute'>
          <child>laser</child>
          <parent>base_link</parent>
          <axis>
              <xyz>0 0 1</xyz>
              <limit>
                 <lower>0</lower>
                 <upper>0</upper>
              </limit>
          </axis>
      </joint>

  </model>
</sdf>
