<robot
  name="scipio_simulation">
  <link
    name="base_link">
    <inertial>
      <origin
        xyz="0.008086959153107 0.174209145980052 -5.10790485504577E-07"
        rpy="0 0 0" />
      <mass
        value="30.6647765845264" />
      <inertia
        ixx="2.53654569364871"
        ixy="-0.0102253079975036"
        ixz="1.17409205479314E-05"
        iyy="4.29925749203646"
        iyz="1.93444165099099E-07"
        izz="2.13275557091149" />
    </inertial>
    <visual>
      <origin
        xyz="0 0 0"
        rpy="0 0 0" />
      <geometry>
        <mesh
          filename="package://scipio_simulation/meshes/base_link.STL" />
      </geometry>
      <material
        name="">
        <color
          rgba="0.752941176470588 0.752941176470588 0.752941176470588 1" />
      </material>
    </visual>
    <collision>
      <origin
        xyz="0 0 0"
        rpy="0 0 0" />
      <geometry>
        <mesh
          filename="package://scipio_simulation/meshes/base_link.STL" />
      </geometry>
    </collision>
  </link>
  <link
    name="front_right_wheel_link">
    <inertial>
      <origin
        xyz="0.24702 -8.6541E-07 -7.5292E-06"
        rpy="0 0 0" />
      <mass
        value="11.018" />
      <inertia
        ixx="0.20289"
        ixy="4.8698E-07"
        ixz="4.2592E-06"
        iyy="0.1147"
        iyz="-8.183E-08"
        izz="0.1147" />
    </inertial>
    <visual>
      <origin
        xyz="0 0 0"
        rpy="0 0 0" />
      <geometry>
        <mesh
          filename="package://scipio_simulation/meshes/front_right_wheel_link.STL" />
      </geometry>
      <material
        name="">
        <color
          rgba="0.75294 0.75294 0.75294 1" />
      </material>
    </visual>
    <collision>
      <origin
        xyz="0 0 0"
        rpy="0 0 0" />
      <geometry>
        <mesh
          filename="package://scipio_simulation/meshes/front_right_wheel_link.STL" />
      </geometry>
    </collision>
  </link>
  <joint
    name="front_right_wheel_joint"
    type="continuous">
    <origin
      xyz="-0.26746 0.17757 0.18923"
      rpy="-3.1282 6.123E-17 1.5708" />
    <parent
      link="base_link" />
    <child
      link="front_right_wheel_link" />
    <axis
      xyz="1 0 0" />
  </joint>
  <link
    name="front_left_wheel_link">
    <inertial>
      <origin
        xyz="0.24702 -6.9913E-07 7.5465E-06"
        rpy="0 0 0" />
      <mass
        value="11.018" />
      <inertia
        ixx="0.20289"
        ixy="3.9801E-07"
        ixz="-4.2684E-06"
        iyy="0.1147"
        iyz="6.9259E-08"
        izz="0.1147" />
    </inertial>
    <visual>
      <origin
        xyz="0 0 0"
        rpy="0 0 0" />
      <geometry>
        <mesh
          filename="package://scipio_simulation/meshes/front_left_wheel_link.STL" />
      </geometry>
      <material
        name="">
        <color
          rgba="0.75294 0.75294 0.75294 1" />
      </material>
    </visual>
    <collision>
      <origin
        xyz="0 0 0"
        rpy="0 0 0" />
      <geometry>
        <mesh
          filename="package://scipio_simulation/meshes/front_left_wheel_link.STL" />
      </geometry>
    </collision>
  </link>
  <joint
    name="front_left_wheel_joint"
    type="continuous">
    <origin
      xyz="-0.26746 -0.17757 0.18923"
      rpy="3.0516 -6.123E-17 -1.5708" />
    <parent
      link="base_link" />
    <child
      link="front_left_wheel_link" />
    <axis
      xyz="-1 0 0" />
  </joint>
  <link
    name="back_right_wheel_link">
    <inertial>
      <origin
        xyz="0.24702 -2.4732E-06 -7.1639E-06"
        rpy="0 0 0" />
      <mass
        value="11.018" />
      <inertia
        ixx="0.20289"
        ixy="1.3965E-06"
        ixz="4.0531E-06"
        iyy="0.1147"
        iyz="-2.2566E-07"
        izz="0.1147" />
    </inertial>
    <visual>
      <origin
        xyz="0 0 0"
        rpy="0 0 0" />
      <geometry>
        <mesh
          filename="package://scipio_simulation/meshes/back_right_wheel_link.STL" />
      </geometry>
      <material
        name="">
        <color
          rgba="0.75294 0.75294 0.75294 1" />
      </material>
    </visual>
    <collision>
      <origin
        xyz="0 0 0"
        rpy="0 0 0" />
      <geometry>
        <mesh
          filename="package://scipio_simulation/meshes/back_right_wheel_link.STL" />
      </geometry>
    </collision>
  </link>
  <joint
    name="back_right_wheel_joint"
    type="continuous">
    <origin
      xyz="0.26746 0.17757 0.18923"
      rpy="-3.0192 6.123E-17 1.5708" />
    <parent
      link="base_link" />
    <child
      link="back_right_wheel_link" />
    <axis
      xyz="1 0 0" />
  </joint>
  <link
    name="back_left_wheel_link">
    <inertial>
      <origin
        xyz="0.24702 -3.7896E-07 7.5693E-06"
        rpy="0 0 0" />
      <mass
        value="11.018" />
      <inertia
        ixx="0.20289"
        ixy="2.1691E-07"
        ixz="-4.2814E-06"
        iyy="0.1147"
        iyz="3.8435E-08"
        izz="0.1147" />
    </inertial>
    <visual>
      <origin
        xyz="0 0 0"
        rpy="0 0 0" />
      <geometry>
        <mesh
          filename="package://scipio_simulation/meshes/back_left_wheel_link.STL" />
      </geometry>
      <material
        name="">
        <color
          rgba="0.75294 0.75294 0.75294 1" />
      </material>
    </visual>
    <collision>
      <origin
        xyz="0 0 0"
        rpy="0 0 0" />
      <geometry>
        <mesh
          filename="package://scipio_simulation/meshes/back_left_wheel_link.STL" />
      </geometry>
    </collision>
  </link>
  <joint
    name="back_left_wheel_joint"
    type="continuous">
    <origin
      xyz="0.26746 -0.17757 0.18923"
      rpy="3.0728 -6.123E-17 -1.5708" />
    <parent
      link="base_link" />
    <child
      link="back_left_wheel_link" />
    <axis
      xyz="-1 0 0" />
  </joint>
</robot>